Traceback (most recent call last):
  File "/Users/tinkavalentijn/.virtualenvs/antact/lib/python3.8/site-packages/jupyter_cache/executors/utils.py", line 51, in single_nb_execution
    executenb(
  File "/Users/tinkavalentijn/.virtualenvs/antact/lib/python3.8/site-packages/nbclient/client.py", line 1112, in execute
    return NotebookClient(nb=nb, resources=resources, km=km, **kwargs).execute()
  File "/Users/tinkavalentijn/.virtualenvs/antact/lib/python3.8/site-packages/nbclient/util.py", line 74, in wrapped
    return just_run(coro(*args, **kwargs))
  File "/Users/tinkavalentijn/.virtualenvs/antact/lib/python3.8/site-packages/nbclient/util.py", line 53, in just_run
    return loop.run_until_complete(coro)
  File "/Users/tinkavalentijn/.pyenv/versions/3.8.5/lib/python3.8/asyncio/base_events.py", line 616, in run_until_complete
    return future.result()
  File "/Users/tinkavalentijn/.virtualenvs/antact/lib/python3.8/site-packages/nbclient/client.py", line 553, in async_execute
    await self.async_execute_cell(
  File "/Users/tinkavalentijn/.virtualenvs/antact/lib/python3.8/site-packages/nbclient/client.py", line 857, in async_execute_cell
    self._check_raise_for_error(cell, exec_reply)
  File "/Users/tinkavalentijn/.virtualenvs/antact/lib/python3.8/site-packages/nbclient/client.py", line 760, in _check_raise_for_error
    raise CellExecutionError.from_cell_and_msg(cell, exec_reply_content)
nbclient.exceptions.CellExecutionError: An error occurred while executing the following cell:
------------------
g=iri_clip.where(iri_clip.F.dt.month.isin([3]), drop=True).sel(L=1,C=0).prob.plot(
    col="F",
    col_wrap=3,
    cmap=mpl.cm.YlOrRd,
    cbar_kwargs={
        "orientation": "horizontal",
        "shrink": 0.8,
        "aspect": 40,
        "pad": 0.1,
    },
    figsize=(20,20)
)
df_bound = gpd.read_file(adm1_bound_path)
for ax in g.axes.flat:
    df_bound.boundary.plot(linewidth=1, ax=ax, color="red")
    ax.axis("off")
------------------

[0;31m---------------------------------------------------------------------------[0m
[0;31mNameError[0m                                 Traceback (most recent call last)
[0;32m<ipython-input-18-95281ffc89fd>[0m in [0;36m<module>[0;34m[0m
[0;32m----> 1[0;31m g=iri_clip.where(iri_clip.F.dt.month.isin([3]), drop=True).sel(L=1,C=0).prob.plot(
[0m[1;32m      2[0m     [0mcol[0m[0;34m=[0m[0;34m"F"[0m[0;34m,[0m[0;34m[0m[0;34m[0m[0m
[1;32m      3[0m     [0mcol_wrap[0m[0;34m=[0m[0;36m3[0m[0;34m,[0m[0;34m[0m[0;34m[0m[0m
[1;32m      4[0m     [0mcmap[0m[0;34m=[0m[0mmpl[0m[0;34m.[0m[0mcm[0m[0;34m.[0m[0mYlOrRd[0m[0;34m,[0m[0;34m[0m[0;34m[0m[0m
[1;32m      5[0m     cbar_kwargs={

[0;31mNameError[0m: name 'iri_clip' is not defined
NameError: name 'iri_clip' is not defined

